Workbook

Sheet BRITA
A1: 仓库ID | B1: 客户 | C1: 产品 | D1: 中文描述 | E1: 英文描述 | F1: 批次 | G1: 库位 | H1: 跟踪号 | I1: LPN | J1: 单位 | K1: 库存数量 | L1: 分配数量 | M1: 冻结数量 | N1: 可用数量 | O1: 订单数 | P1: 补货待下架数量 | Q1: 补货待上架数量 | R1: 待上架数量 | S1: 待移出数量 | T1: 待移入数量 | U1: 待调整数量 | V1: 体积 | W1: 毛重 | X1: 净重 | Y1: 价值 | Z1: 自定义1 | AA1: 自定义2 | AB1: 自定义3 | AC1: 生产日期 | AD1: 失效日期 | AE1: 入库日期 | AF1: 生产批号 | AG1: SAP库位 | AH1: 特殊操作 | AI1: 质量状态 | AJ1: 托数 | AK1: Age Range | AL1: Category | AM1: Product | AN1: Color | AP1: Age Range
A2: WH01 | B2: BRITA | C2: 1046726 | D2: 矿泉壶,PS透明壶身配亮黑色上盖1支装,Marella XL 1046726 | E2: * | F2: LT00048387 | G2: 1A00101 | H2: * | I2: * | J2: EA | K2: 96 | L2: 0 | M2: 0 | N2: 96 | P2: 0 | Q2: 0 | R2: 0 | S2: 0 | T2: 0 | U2: 0 | V2: 0 | W2: 0 | X2: 0 | Y2: 0 | AC2: 2024-04-02 | AD2: 2033-04-02 | AE2: 2024-04-02 | AF2: KI4121 | AG2: 1020UR | AI2: N | AJ2: 1 | AK2: =IF(AJ2>$AP$2,$AQ$2,IF(AJ2>$AP$3,$AQ$3,IF(AJ2>$AP$4,$AQ$4,$AQ$5))) -> =<90 | AL2: =VLOOKUP(C:C,[1]基础信息!B$1:D$65536,3,0) -> Jug | AM2: =VLOOKUP(C:C,[1]基础信息!B$1:E$65536,4,0) -> Marella XL | AN2: =VLOOKUP(C:C,[1]基础信息!B$1:F$65536,5,0) -> Black | AP2: 360 | AQ2: >360
A3: WH01 | B3: BRITA | C3: 1049197 | D3: 矿泉壶,PS透明壶身配蓝色上盖12支装,,Green Pack 1049197 | E3: * | F3: LT00049548 | G3: 1A00102 | H3: 0000369439 | J3: EA | K3: 31 | L3: 0 | M3: 0 | N3: 31 | P3: 0 | Q3: 0 | R3: 0 | S3: 0 | T3: 0 | U3: 0 | V3: 0 | W3: 0 | X3: 0 | Y3: 0 | AC3: 2024-04-28 | AD3: 2031-04-28 | AE3: 2024-04-28 | AF3: KI4174 | AG3: 1020UR | AI3: N | AJ3: 1 | AK3: =IF(AJ3>$AP$2,$AQ$2,IF(AJ3>$AP$3,$AQ$3,IF(AJ3>$AP$4,$AQ$4,$AQ$5))) -> =<90 | AL3: =VLOOKUP(C:C,[1]基础信息!B$1:D$65536,3,0) -> Jug | AM3: =VLOOKUP(C:C,[1]基础信息!B$1:E$65536,4,0) -> Marella XL | AN3: =VLOOKUP(C:C,[1]基础信息!B$1:F$65536,5,0) -> Blue | AP3: 180 | AQ3: 181-360
A4: WH01 | B4: BRITA | C4: 1049197 | D4: 矿泉壶,PS透明壶身配蓝色上盖12支装,,Green Pack 1049197 | E4: * | F4: LT00049548 | G4: 1A00103 | H4: 0000369440 | J4: EA | K4: 72 | L4: 0 | M4: 0 | N4: 72 | P4: 0 | Q4: 0 | R4: 0 | S4: 0 | T4: 0 | U4: 0 | V4: 0 | W4: 0 | X4: 0 | Y4: 0 | AC4: 2024-04-28 | AD4: 2031-04-28 | AE4: 2024-04-28 | AF4: KI4174 | AG4: 1020UR | AI4: N | AJ4: 1 | AK4: =IF(AJ4>$AP$2,$AQ$2,IF(AJ4>$AP$3,$AQ$3,IF(AJ4>$AP$4,$AQ$4,$AQ$5))) -> =<90 | AL4: =VLOOKUP(C:C,[1]基础信息!B$1:D$65536,3,0) -> Jug | AM4: =VLOOKUP(C:C,[1]基础信息!B$1:E$65536,4,0) -> Marella XL | AN4: =VLOOKUP(C:C,[1]基础信息!B$1:F$65536,5,0) -> Blue | AP4: 90 | AQ4: 91-180
A5: WH01 | B5: BRITA | C5: 1053318 | D5: F&B Dispen Ladoga MXplus UVC Whi CU CN | E5: * | F5: LT00052270 | G5: 1A00104 | H5: 0000372099 | J5: EA | K5: 36 | L5: 0 | M5: 0 | N5: 36 | P5: 0 | Q5: 0 | R5: 0 | S5: 0 | T5: 0 | U5: 0 | V5: 0 | W5: 0 | X5: 0 | Y5: 0 | AC5: 2024-05-10 | AD5: 2031-05-10 | AE5: 2024-05-10 | AF5: WH4192 | AG5: 1011UR | AI5: N | AJ5: 1 | AK5: =IF(AJ5>$AP$2,$AQ$2,IF(AJ5>$AP$3,$AQ$3,IF(AJ5>$AP$4,$AQ$4,$AQ$5))) -> =<90 | AL5: =VLOOKUP(C:C,[1]基础信息!B$1:D$65536,3,0) -> Hotcup | AM5: =VLOOKUP(C:C,[1]基础信息!B$1:E$65536,4,0) -> Hotcup | AN5: =VLOOKUP(C:C,[1]基础信息!B$1:F$65536,5,0) -> Whi | AQ5: =<90
A6: WH01 | B6: BRITA | C6: 1053318 | D6: F&B Dispen Ladoga MXplus UVC Whi CU CN | E6: * | F6: LT00052270 | G6: 1A00105 | H6: 0000372100 | J6: EA | K6: 36 | L6: 0 | M6: 0 | N6: 36 | P6: 0 | Q6: 0 | R6: 0 | S6: 0 | T6: 0 | U6: 0 | V6: 0 | W6: 0 | X6: 0 | Y6: 0 | AC6: 2024-05-10 | AD6: 2031-05-10 | AE6: 2024-05-10 | AF6: WH4192 | AG6: 1011UR | AI6: N | AJ6: 1 | AK6: =IF(AJ6>$AP$2,$AQ$2,IF(AJ6>$AP$3,$AQ$3,IF(AJ6>$AP$4,$AQ$4,$AQ$5))) -> =<90 | AL6: =VLOOKUP(C:C,[1]基础信息!B$1:D$65536,3,0) -> Hotcup | AM6: =VLOOKUP(C:C,[1]基础信息!B$1:E$65536,4,0) -> Hotcup | AN6: =VLOOKUP(C:C,[1]基础信息!B$1:F$65536,5,0) -> Whi
A7: WH01 | B7: BRITA | C7: 1053318 | D7: F&B Dispen Ladoga MXplus UVC Whi CU CN | E7: * | F7: LT00052271 | G7: 1A00201 | H7: * | J7: EA | K7: 36 | L7: 0 | M7: 0 | N7: 36 | P7: 0 | Q7: 0 | R7: 0 | S7: 0 | T7: 0 | U7: 0 | V7: 0 | W7: 0 | X7: 0 | Y7: 0 | AC7: 2024-05-10 | AD7: 2031-05-10 | AE7: 2024-05-10 | AF7: WH4186 | AG7: 1011UR | AI7: N | AJ7: 1 | AK7: =IF(AJ7>$AP$2,$AQ$2,IF(AJ7>$AP$3,$AQ$3,IF(AJ7>$AP$4,$AQ$4,$AQ$5))) -> =<90 | AL7: =VLOOKUP(C:C,[1]基础信息!B$1:D$65536,3,0) -> Hotcup | AM7: =VLOOKUP(C:C,[1]基础信息!B$1:E$65536,4,0) -> Hotcup | AN7: =VLOOKUP(C:C,[1]基础信息!B$1:F$65536,5,0) -> Whi
A8: WH01 | B8: BRITA | C8: 1045641 | D8: "Style XL LED4W Mxplus blue NT CU CNO_x000D_ 滤水壶; Style 中国蓝 一壶一芯" | E8: * | F8: LT00051320 | G8: 1A00202 | H8: 0000377378 | J8: EA | K8: 96 | L8: 0 | M8: 0 | N8: 96 | P8: 0 | Q8: 0 | R8: 0 | S8: 0 | T8: 0 | U8: 0 | V8: 0 | W8: 0 | X8: 0 | Y8: 0 | AC8: 2024-06-15 | AD8: 2031-06-15 | AE8: 2024-06-15 | AF8: YE4236S2 | AG8: 1020UR | AI8: N | AJ8: 1 | AK8: =IF(AJ8>$AP$2,$AQ$2,IF(AJ8>$AP$3,$AQ$3,IF(AJ8>$AP$4,$AQ$4,$AQ$5))) -> =<90 | AL8: =VLOOKUP(C:C,[1]基础信息!B$1:D$65536,3,0) -> Jug | AM8: =VLOOKUP(C:C,[1]基础信息!B$1:E$65536,4,0) -> Mxplus | AN8: =VLOOKUP(C:C,[1]基础信息!B$1:F$65536,5,0) -> Blue
A9: WH01 | B9: BRITA | C9: 1045641 | D9: "Style XL LED4W Mxplus blue NT CU CNO_x000D_ 滤水壶; Style 中国蓝 一壶一芯" | E9: * | F9: LT00051320 | G9: 1A00203 | H9: 0000377379 | J9: EA | K9: 96 | L9: 0 | M9: 0 | N9: 96 | P9: 0 | Q9: 0 | R9: 0 | S9: 0 | T9: 0 | U9: 0 | V9: 0 | W9: 0 | X9: 0 | Y9: 0 | AC9: 2024-06-15 | AD9: 2031-06-15 | AE9: 2024-06-15 | AF9: YE4236S2 | AG9: 1020UR | AI9: N | AJ9: 1 | AK9: =IF(AJ9>$AP$2,$AQ$2,IF(AJ9>$AP$3,$AQ$3,IF(AJ9>$AP$4,$AQ$4,$AQ$5))) -> =<90 | AL9: =VLOOKUP(C:C,[1]基础信息!B$1:D$65536,3,0) -> Jug | AM9: =VLOOKUP(C:C,[1]基础信息!B$1:E$65536,4,0) -> Mxplus | AN9: =VLOOKUP(C:C,[1]基础信息!B$1:F$65536,5,0) -> Blue
A10: WH01 | B10: BRITA | C10: 1036009 | D10: Refill Fika mypure pro CB CN | E10: * | F10: LT00045427 | G10: 1A00204 | H10: 0000353662 | J10: EA | K10: 20 | L10: 0 | M10: 0 | N10: 20 | P10: 0 | Q10: 0 | R10: 0 | S10: 0 | T10: 0 | U10: 0 | V10: 0 | W10: 0 | X10: 0 | Y10: 0 | AC10: 2024-01-09 | AD10: 2031-01-09 | AE10: 2024-01-10 | AF10: 0006207536 | AG10: 1020UR | AI10: N | AJ10: 1 | AK10: =IF(AJ10>$AP$2,$AQ$2,IF(AJ10>$AP$3,$AQ$3,IF(AJ10>$AP$4,$AQ$4,$AQ$5))) -> =<90 | AL10: =VLOOKUP(C:C,[1]基础信息!B$1:D$65536,3,0) -> UTS | AM10: =VLOOKUP(C:C,[1]基础信息!B$1:E$65536,4,0) -> MyPure Pro | AN10: =VLOOKUP(C:C,[1]基础信息!B$1:F$65536,5,0) -> Refill
A11: WH01 | B11: BRITA | C11: 1053318 | D11: F&B Dispen Ladoga MXplus UVC Whi CU CN | E11: * | F11: LT00052270 | G11: 1A00205 | H11: 0000372101 | J11: EA | K11: 36 | L11: 0 | M11: 0 | N11: 36 | P11: 0 | Q11: 0 | R11: 0 | S11: 0 | T11: 0 | U11: 0 | V11: 0 | W11: 0 | X11: 0 | Y11: 0 | AC11: 2024-05-10 | AD11: 2031-05-10 | AE11: 2024-05-10 | AF11: WH4192 | AG11: 1011UR | AI11: N | AJ11: 1 | AK11: =IF(AJ11>$AP$2,$AQ$2,IF(AJ11>$AP$3,$AQ$3,IF(AJ11>$AP$4,$AQ$4,$AQ$5))) -> =<90 | AL11: =VLOOKUP(C:C,[1]基础信息!B$1:D$65536,3,0) -> Hotcup | AM11: =VLOOKUP(C:C,[1]基础信息!B$1:E$65536,4,0) -> Hotcup | AN11: =VLOOKUP(C:C,[1]基础信息!B$1:F$65536,5,0) -> Whi
A12: WH01 | B12: BRITA | C12: 1046537 | D12: 矿泉壶,PS透明壶身配蓝色上盖1支装,Marella XL 1046537 | E12: 1046537 | F12: LT00050853 | G12: 1A00302 | H12: 0000375652 | J12: EA | K12: 96 | L12: 0 | M12: 0 | N12: 96 | P12: 0 | Q12: 0 | R12: 0 | S12: 0 | T12: 0 | U12: 0 | V12: 0 | W12: 0 | X12: 0 | Y12: 0 | AC12: 2024-06-01 | AD12: 2031-06-01 | AE12: 2024-06-01 | AF12: KI4227 | AG12: 1020UR | AI12: N | AJ12: 1 | AK12: =IF(AJ12>$AP$2,$AQ$2,IF(AJ12>$AP$3,$AQ$3,IF(AJ12>$AP$4,$AQ$4,$AQ$5))) -> =<90 | AL12: =VLOOKUP(C:C,[1]基础信息!B$1:D$65536,3,0) -> Jug | AM12: =VLOOKUP(C:C,[1]基础信息!B$1:E$65536,4,0) -> Marella XL | AN12: =VLOOKUP(C:C,[1]基础信息!B$1:F$65536,5,0) -> Blue
A13: WH01 | B13: BRITA | C13: 1036010 | D13: Refill Fika mypure pro CB-UF CN | E13: * | F13: LT00050982 | G13: 1A00303 | H13: 0000376239 | J13: EA | K13: 20 | L13: 0 | M13: 0 | N13: 20 | P13: 0 | Q13: 0 | R13: 0 | S13: 0 | T13: 0 | U13: 0 | V13: 0 | W13: 0 | X13: 0 | Y13: 0 | AC13: 2024-06-06 | AD13: 2031-06-06 | AE13: 2024-06-06 | AF13: 0006229620 | AG13: 1020UR | AI13: N | AJ13: 1 | AK13: =IF(AJ13>$AP$2,$AQ$2,IF(AJ13>$AP$3,$AQ$3,IF(AJ13>$AP$4,$AQ$4,$AQ$5))) -> =<90 | AL13: =VLOOKUP(C:C,[1]基础信息!B$1:D$65536,3,0) -> UTS | AM13: =VLOOKUP(C:C,[1]基础信息!B$1:E$65536,4,0) -> MyPure Pro | AN13: =VLOOKUP(C:C,[1]基础信息!B$1:F$65536,5,0) -> Refill
A14: WH01 | B14: BRITA | C14: 1045641 | D14: "Style XL LED4W Mxplus blue NT CU CNO_x000D_ 滤水壶; Style 中国蓝 一壶一芯" | E14: * | F14: LT00051320 | G14: 1A00304 | H14: 0000377380 | J14: EA | K14: 96 | L14: 0 | M14: 0 | N14: 96 | P14: 0 | Q14: 0 | R14: 0 | S14: 0 | T14: 0 | U14: 0 | V14: 0 | W14: 0 | X14: 0 | Y14: 0 | AC14: 2024-06-15 | AD14: 2031-06-15 | AE14: 2024-06-15 | AF14: YE4236S2 | AG14: 1020UR | AI14: N | AJ14: 1 | AK14: =IF(AJ14>$AP$2,$AQ$2,IF(AJ14>$AP$3,$AQ$3,IF(AJ14>$AP$4,$AQ$4,$AQ$5))) -> =<90 | AL14: =VLOOKUP(C:C,[1]基础信息!B$1:D$65536,3,0) -> Jug | AM14: =VLOOKUP(C:C,[1]基础信息!B$1:E$65536,4,0) -> Mxplus | AN14: =VLOOKUP(C:C,[1]基础信息!B$1:F$65536,5,0) -> Blue
A15: WH01 | B15: BRITA | C15: 1045641 | D15: "Style XL LED4W Mxplus blue NT CU CNO_x000D_ 滤水壶; Style 中国蓝 一壶一芯" | E15: * | F15: LT00051320 | G15: 1A00305 | H15: 0000377381 | J15: EA | K15: 96 | L15: 0 | M15: 0 | N15: 96 | P15: 0 | Q15: 0 | R15: 0 | S15: 0 | T15: 0 | U15: 0 | V15: 0 | W15: 0 | X15: 0 | Y15: 0 | AC15: 2024-06-15 | AD15: 2031-06-15 | AE15: 2024-06-15 | AF15: YE4236S2 | AG15: 1020UR | AI15: N | AJ15: 1 | AK15: =IF(AJ15>$AP$2,$AQ$2,IF(AJ15>$AP$3,$AQ$3,IF(AJ15>$AP$4,$AQ$4,$AQ$5))) -> =<90 | AL15: =VLOOKUP(C:C,[1]基础信息!B$1:D$65536,3,0) -> Jug | AM15: =VLOOKUP(C:C,[1]基础信息!B$1:E$65536,4,0) -> Mxplus | AN15: =VLOOKUP(C:C,[1]基础信息!B$1:F$65536,5,0) -> Blue
A16: WH01 | B16: BRITA | C16: 1046726 | D16: 矿泉壶,PS透明壶身配亮黑色上盖1支装,Marella XL 1046726 | E16: * | F16: LT00048387 | G16: 1A00401 | H16: * | I16: * | J16: EA | K16: 96 | L16: 0 | M16: 0 | N16: 96 | P16: 0 | Q16: 0 | R16: 0 | S16: 0 | T16: 0 | U16: 0 | V16: 0 | W16: 0 | X16: 0 | Y16: 0 | AC16: 2024-04-02 | AD16: 2033-04-02 | AE16: 2024-04-02 | AF16: KI4121 | AG16: 1020UR | AI16: N | AJ16: 1 | AK16: =IF(AJ16>$AP$2,$AQ$2,IF(AJ16>$AP$3,$AQ$3,IF(AJ16>$AP$4,$AQ$4,$AQ$5))) -> =<90 | AL16: =VLOOKUP(C:C,[1]基础信息!B$1:D$65536,3,0) -> Jug | AM16: =VLOOKUP(C:C,[1]基础信息!B$1:E$65536,4,0) -> Marella XL | AN16: =VLOOKUP(C:C,[1]基础信息!B$1:F$65536,5,0) -> Black
A17: WH01 | B17: BRITA | C17: 1046537 | D17: 矿泉壶,PS透明壶身配蓝色上盖1支装,Marella XL 1046537 | E17: 1046537 | F17: LT00050065 | G17: 1A00402 | H17: 0000372416 | J17: EA | K17: 92 | L17: 0 | M17: 0 | N17: 92 | P17: 0 | Q17: 0 | R17: 0 | S17: 0 | T17: 0 | U17: 0 | V17: 0 | W17: 0 | X17: 0 | Y17: 0 | AC17: 2024-05-13 | AD17: 2031-05-13 | AE17: 2024-05-13 | AF17: KI4196 | AG17: 1020UR | AI17: N | AJ17: 1 | AK17: =IF(AJ17>$AP$2,$AQ$2,IF(AJ17>$AP$3,$AQ$3,IF(AJ17>$AP$4,$AQ$4,$AQ$5))) -> =<90 | AL17: =VLOOKUP(C:C,[1]基础信息!B$1:D$65536,3,0) -> Jug | AM17: =VLOOKUP(C:C,[1]基础信息!B$1:E$65536,4,0) -> Marella XL | AN17: =VLOOKUP(C:C,[1]基础信息!B$1:F$65536,5,0) -> Blue
A18: WH01 | B18: BRITA | C18: 1045641 | D18: "Style XL LED4W Mxplus blue NT CU CNO_x000D_ 滤水壶; Style 中国蓝 一壶一芯" | E18: * | F18: LT00051320 | G18: 1A00403 | H18: 0000377382 | J18: EA | K18: 96 | L18: 0 | M18: 0 | N18: 96 | P18: 0 | Q18: 0 | R18: 0 | S18: 0 | T18: 0 | U18: 0 | V18: 0 | W18: 0 | X18: 0 | Y18: 0 | AC18: 2024-06-15 | AD18: 2031-06-15 | AE18: 2024-06-15 | AF18: YE4236S2 | AG18: 1020UR | AI18: N | AJ18: 1 | AK18: =IF(AJ18>$AP$2,$AQ$2,IF(AJ18>$AP$3,$AQ$3,IF(AJ18>$AP$4,$AQ$4,$AQ$5))) -> =<90 | AL18: =VLOOKUP(C:C,[1]基础信息!B$1:D$65536,3,0) -> Jug | AM18: =VLOOKUP(C:C,[1]基础信息!B$1:E$65536,4,0) -> Mxplus | AN18: =VLOOKUP(C:C,[1]基础信息!B$1:F$65536,5,0) -> Blue
A19: WH01 | B19: BRITA | C19: 1046537 | D19: 矿泉壶,PS透明壶身配蓝色上盖1支装,Marella XL 1046537 | E19: 1046537 | F19: LT00050853 | G19: 1A00404 | H19: 0000375653 | J19: EA | K19: 96 | L19: 0 | M19: 0 | N19: 96 | P19: 0 | Q19: 0 | R19: 0 | S19: 0 | T19: 0 | U19: 0 | V19: 0 | W19: 0 | X19: 0 | Y19: 0 | AC19: 2024-06-01 | AD19: 2031-06-01 | AE19: 2024-06-01 | AF19: KI4227 | AG19: 1020UR | AI19: N | AJ19: 1 | AK19: =IF(AJ19>$AP$2,$AQ$2,IF(AJ19>$AP$3,$AQ$3,IF(AJ19>$AP$4,$AQ$4,$AQ$5))) -> =<90 | AL19: =VLOOKUP(C:C,[1]基础信息!B$1:D$65536,3,0) -> Jug | AM19: =VLOOKUP(C:C,[1]基础信息!B$1:E$65536,4,0) -> Marella XL | AN19: =VLOOKUP(C:C,[1]基础信息!B$1:F$65536,5,0) -> Blue
A20: WH01 | B20: BRITA | C20: 1053318 | D20: F&B Dispen Ladoga MXplus UVC Whi CU CN | E20: * | F20: LT00052271 | G20: 1A00405 | H20: 0000372102 | J20: EA | K20: 36 | L20: 0 | M20: 0 | N20: 36 | P20: 0 | Q20: 0 | R20: 0 | S20: 0 | T20: 0 | U20: 0 | V20: 0 | W20: 0 | X20: 0 | Y20: 0 | AC20: 2024-05-10 | AD20: 2031-05-10 | AE20: 2024-05-10 | AF20: WH4186 | AG20: 1011UR | AI20: N | AJ20: 1 | AK20: =IF(AJ20>$AP$2,$AQ$2,IF(AJ20>$AP$3,$AQ$3,IF(AJ20>$AP$4,$AQ$4,$AQ$5))) -> =<90 | AL20: =VLOOKUP(C:C,[1]基础信息!B$1:D$65536,3,0) -> Hotcup | AM20: =VLOOKUP(C:C,[1]基础信息!B$1:E$65536,4,0) -> Hotcup | AN20: =VLOOKUP(C:C,[1]基础信息!B$1:F$65536,5,0) -> Whi
A21: WH01 | B21: BRITA | C21: 1046537 | D21: 矿泉壶,PS透明壶身配蓝色上盖1支装,Marella XL 1046537 | E21: 1046537 | F21: LT00050853 | G21: 1A00502 | H21: 0000375654 | J21: EA | K21: 96 | L21: 0 | M21: 0 | N21: 96 | P21: 0 | Q21: 0 | R21: 0 | S21: 0 | T21: 0 | U21: 0 | V21: 0 | W21: 0 | X21: 0 | Y21: 0 | AC21: 2024-06-01 | AD21: 2031-06-01 | AE21: 2024-06-01 | AF21: KI4227 | AG21: 1020UR | AI21: N | AJ21: 1 | AK21: =IF(AJ21>$AP$2,$AQ$2,IF(AJ21>$AP$3,$AQ$3,IF(AJ21>$AP$4,$AQ$4,$AQ$5))) -> =<90 | AL21: =VLOOKUP(C:C,[1]基础信息!B$1:D$65536,3,0) -> Jug | AM21: =VLOOKUP(C:C,[1]基础信息!B$1:E$65536,4,0) -> Marella XL | AN21: =VLOOKUP(C:C,[1]基础信息!B$1:F$65536,5,0) -> Blue
A22: WH01 | B22: BRITA | C22: 1045641 | D22: "Style XL LED4W Mxplus blue NT CU CNO_x000D_ 滤水壶; Style 中国蓝 一壶一芯" | E22: * | F22: LT00051320 | G22: 1A00503 | H22: 0000377383 | J22: EA | K22: 96 | L22: 0 | M22: 0 | N22: 96 | P22: 0 | Q22: 0 | R22: 0 | S22: 0 | T22: 0 | U22: 0 | V22: 0 | W22: 0 | X22: 0 | Y22: 0 | AC22: 2024-06-15 | AD22: 2031-06-15 | AE22: 2024-06-15 | AF22: YE4236S2 | AG22: 1020UR | AI22: N | AJ22: 1 | AK22: =IF(AJ22>$AP$2,$AQ$2,IF(AJ22>$AP$3,$AQ$3,IF(AJ22>$AP$4,$AQ$4,$AQ$5))) -> =<90 | AL22: =VLOOKUP(C:C,[1]基础信息!B$1:D$65536,3,0) -> Jug | AM22: =VLOOKUP(C:C,[1]基础信息!B$1:E$65536,4,0) -> Mxplus | AN22: =VLOOKUP(C:C,[1]基础信息!B$1:F$65536,5,0) -> Blue
A23: WH01 | B23: BRITA | C23: 1036010 | D23: Refill Fika mypure pro CB-UF CN | E23: * | F23: LT00052264 | G23: 1A00504 | H23: 0000380812 | J23: EA | K23: 120 | L23: 0 | M23: 0 | N23: 120 | P23: 0 | Q23: 0 | R23: 0 | S23: 0 | T23: 0 | U23: 0 | V23: 0 | W23: 0 | X23: 0 | Y23: 0 | AC23: 2024-07-09 | AD23: 2031-07-09 | AE23: 2024-07-09 | AF23: 0006226547 | AG23: 1020UR | AI23: N | AJ23: 1 | AK23: =IF(AJ23>$AP$2,$AQ$2,IF(AJ23>$AP$3,$AQ$3,IF(AJ23>$AP$4,$AQ$4,$AQ$5))) -> =<90 | AL23: =VLOOKUP(C:C,[1]基础信息!B$1:D$65536,3,0) -> UTS | AM23: =VLOOKUP(C:C,[1]基础信息!B$1:E$65536,4,0) -> MyPure Pro | AN23: =VLOOKUP(C:C,[1]基础信息!B$1:F$65536,5,0) -> Refill
A24: WH01 | B24: BRITA | C24: 1045641 | D24: "Style XL LED4W Mxplus blue NT CU CNO_x000D_ 滤水壶; Style 中国蓝 一壶一芯" | E24: * | F24: LT00051320 | G24: 1A00505 | H24: 0000377384 | J24: EA | K24: 96 | L24: 0 | M24: 0 | N24: 96 | P24: 0 | Q24: 0 | R24: 0 | S24: 0 | T24: 0 | U24: 0 | V24: 0 | W24: 0 | X24: 0 | Y24: 0 | AC24: 2024-06-15 | AD24: 2031-06-15 | AE24: 2024-06-15 | AF24: YE4236S2 | AG24: 1020UR | AI24: N | AJ24: 1 | AK24: =IF(AJ24>$AP$2,$AQ$2,IF(AJ24>$AP$3,$AQ$3,IF(AJ24>$AP$4,$AQ$4,$AQ$5))) -> =<90 | AL24: =VLOOKUP(C:C,[1]基础信息!B$1:D$65536,3,0) -> Jug | AM24: =VLOOKUP(C:C,[1]基础信息!B$1:E$65536,4,0) -> Mxplus | AN24: =VLOOKUP(C:C,[1]基础信息!B$1:F$65536,5,0) -> Blue
A25: WH01 | B25: BRITA | C25: 1046537 | D25: 矿泉壶,PS透明壶身配蓝色上盖1支装,Marella XL 1046537 | E25: 1046537 | F25: LT00050853 | G25: 1A00602 | H25: 0000375655 | J25: EA | K25: 96 | L25: 0 | M25: 0 | N25: 96 | P25: 0 | Q25: 0 | R25: 0 | S25: 0 | T25: 0 | U25: 0 | V25: 0 | W25: 0 | X25: 0 | Y25: 0 | AC25: 2024-06-01 | AD25: 2031-06-01 | AE25: 2024-06-01 | AF25: KI4227 | AG25: 1020UR | AI25: N | AJ25: 1 | AK25: =IF(AJ25>$AP$2,$AQ$2,IF(AJ25>$AP$3,$AQ$3,IF(AJ25>$AP$4,$AQ$4,$AQ$5))) -> =<90 | AL25: =VLOOKUP(C:C,[1]基础信息!B$1:D$65536,3,0) -> Jug | AM25: =VLOOKUP(C:C,[1]基础信息!B$1:E$65536,4,0) -> Marella XL | AN25: =VLOOKUP(C:C,[1]基础信息!B$1:F$65536,5,0) -> Blue
A26: WH01 | B26: BRITA | C26: 1046537 | D26: 矿泉壶,PS透明壶身配蓝色上盖1支装,Marella XL 1046537 | E26: 1046537 | F26: LT00050855 | G26: 1A00603 | H26: 0000375656 | J26: EA | K26: 96 | L26: 0 | M26: 0 | N26: 96 | P26: 0 | Q26: 0 | R26: 0 | S26: 0 | T26: 0 | U26: 0 | V26: 0 | W26: 0 | X26: 0 | Y26: 0 | AC26: 2024-06-03 | AD26: 2031-06-03 | AE26: 2024-06-03 | AF26: KI4227 | AG26: 1020UR | AI26: N | AJ26: 1 | AK26: =IF(AJ26>$AP$2,$AQ$2,IF(AJ26>$AP$3,$AQ$3,IF(AJ26>$AP$4,$AQ$4,$AQ$5))) -> =<90 | AL26: =VLOOKUP(C:C,[1]基础信息!B$1:D$65536,3,0) -> Jug | AM26: =VLOOKUP(C:C,[1]基础信息!B$1:E$65536,4,0) -> Marella XL | AN26: =VLOOKUP(C:C,[1]基础信息!B$1:F$65536,5,0) -> Blue
A27: WH01 | B27: BRITA | C27: 1046537 | D27: 矿泉壶,PS透明壶身配蓝色上盖1支装,Marella XL 1046537 | E27: 1046537 | F27: LT00050855 | G27: 1A00604 | H27: 0000375657 | J27: EA | K27: 96 | L27: 0 | M27: 0 | N27: 96 | P27: 0 | Q27: 0 | R27: 0 | S27: 0 | T27: 0 | U27: 0 | V27: 0 | W27: 0 | X27: 0 | Y27: 0 | AC27: 2024-06-03 | AD27: 2031-06-03 | AE27: 2024-06-03 | AF27: KI4227 | AG27: 1020UR | AI27: N | AJ27: 1 | AK27: =IF(AJ27>$AP$2,$AQ$2,IF(AJ27>$AP$3,$AQ$3,IF(AJ27>$AP$4,$AQ$4,$AQ$5))) -> =<90 | AL27: =VLOOKUP(C:C,[1]基础信息!B$1:D$65536,3,0) -> Jug | AM27: =VLOOKUP(C:C,[1]基础信息!B$1:E$65536,4,0) -> Marella XL | AN27: =VLOOKUP(C:C,[1]基础信息!B$1:F$65536,5,0) -> Blue
A28: WH01 | B28: BRITA | C28: 1046537 | D28: 矿泉壶,PS透明壶身配蓝色上盖1支装,Marella XL 1046537 | E28: 1046537 | F28: LT00050855 | G28: 1A00605 | H28: 0000375658 | J28: EA | K28: 96 | L28: 0 | M28: 0 | N28: 96 | P28: 0 | Q28: 0 | R28: 0 | S28: 0 | T28: 0 | U28: 0 | V28: 0 | W28: 0 | X28: 0 | Y28: 0 | AC28: 2024-06-03 | AD28: 2031-06-03 | AE28: 2024-06-03 | AF28: KI4227 | AG28: 1020UR | AI28: N | AJ28: 1 | AK28: =IF(AJ28>$AP$2,$AQ$2,IF(AJ28>$AP$3,$AQ$3,IF(AJ28>$AP$4,$AQ$4,$AQ$5))) -> =<90 | AL28: =VLOOKUP(C:C,[1]基础信息!B$1:D$65536,3,0) -> Jug | AM28: =VLOOKUP(C:C,[1]基础信息!B$1:E$65536,4,0) -> Marella XL | AN28: =VLOOKUP(C:C,[1]基础信息!B$1:F$65536,5,0) -> Blue
... A78: WH01 | B78: BRITA | C78: 1046537 | D78: 矿泉壶,PS透明壶身配蓝色上盖1支装,Marella XL 1046537 | E78: 1046537 | F78: LT00050856 | G78: 1A01902 | H78: 0000375677 | J78: EA | K78: 96 | L78: 0 | M78: 0 | N78: 96 | P78: 0 | Q78: 0 | R78: 0 | S78: 0 | T78: 0 | U78: 0 | V78: 0 | W78: 0 | X78: 0 | Y78: 0 | AC78: 2024-06-03 | AD78: 2031-06-03 | AE78: 2024-06-03 | AF78: KI4221 | AG78: 1020UR | AI78: N | AJ78: 1 | AK78: =IF(AJ78>$AP$2,$AQ$2,IF(AJ78>$AP$3,$AQ$3,IF(AJ78>$AP$4,$AQ$4,$AQ$5))) -> =<90 | AL78: =VLOOKUP(C:C,[1]基础信息!B$1:D$65536,3,0) -> Jug | AM78: =VLOOKUP(C:C,[1]基础信息!B$1:E$65536,4,0) -> Marella XL | AN78: =VLOOKUP(C:C,[1]基础信息!B$1:F$65536,5,0) -> Blue
A79: WH01 | B79: BRITA | C79: 1043270 | D79: "Aluna XL ME4W blue BCM CU CNO | E79: * | F79: LT00047611 | G79: 1A01903 | H79: * | I79: * | J79: EA | K79: 13 | L79: 0 | M79: 0 | N79: 13 | P79: 0 | Q79: 0 | R79: 0 | S79: 0 | T79: 0 | U79: 0 | V79: 0 | W79: 0 | X79: 0 | Y79: 0 | AC79: 2024-03-11 | AD79: 2031-03-11 | AE79: 2024-03-11 | AF79: YE4087A3 | AG79: 1020UR | AI79: N | AJ79: 1 | AK79: =IF(AJ79>$AP$2,$AQ$2,IF(AJ79>$AP$3,$AQ$3,IF(AJ79>$AP$4,$AQ$4,$AQ$5))) -> =<90 | AL79: =VLOOKUP(C:C,[1]基础信息!B$1:D$65536,3,0) -> Jug | AM79: =VLOOKUP(C:C,[1]基础信息!B$1:E$65536,4,0) -> Aluna | AN79: =VLOOKUP(C:C,[1]基础信息!B$1:F$65536,5,0) -> Blue
A80: WH01 | B80: BRITA | C80: 1043270 | D80: "Aluna XL ME4W blue BCM CU CNO | E80: * | F80: LT00047611 | G80: 1A01904 | H80: * | I80: * | J80: EA | K80: 96 | L80: 0 | M80: 0 | N80: 96 | P80: 0 | Q80: 0 | R80: 0 | S80: 0 | T80: 0 | U80: 0 | V80: 0 | W80: 0 | X80: 0 | Y80: 0 | AC80: 2024-03-11 | AD80: 2031-03-11 | AE80: 2024-03-11 | AF80: YE4087A3 | AG80: 1020UR | AI80: N | AJ80: 1 | AK80: =IF(AJ80>$AP$2,$AQ$2,IF(AJ80>$AP$3,$AQ$3,IF(AJ80>$AP$4,$AQ$4,$AQ$5))) -> =<90 | AL80: =VLOOKUP(C:C,[1]基础信息!B$1:D$65536,3,0) -> Jug | AM80: =VLOOKUP(C:C,[1]基础信息!B$1:E$65536,4,0) -> Aluna | AN80: =VLOOKUP(C:C,[1]基础信息!B$1:F$65536,5,0) -> Blue
A81: WH01 | B81: BRITA | C81: 1043270 | D81: "Aluna XL ME4W blue BCM CU CNO | E81: * | F81: LT00047611 | G81: 1A01905 | H81: * | I81: * | J81: EA | K81: 96 | L81: 0 | M81: 0 | N81: 96 | P81: 0 | Q81: 0 | R81: 0 | S81: 0 | T81: 0 | U81: 0 | V81: 0 | W81: 0 | X81: 0 | Y81: 0 | AC81: 2024-03-11 | AD81: 2031-03-11 | AE81: 2024-03-11 | AF81: YE4087A3 | AG81: 1020UR | AI81: N | AJ81: 1 | AK81: =IF(AJ81>$AP$2,$AQ$2,IF(AJ81>$AP$3,$AQ$3,IF(AJ81>$AP$4,$AQ$4,$AQ$5))) -> =<90 | AL81: =VLOOKUP(C:C,[1]基础信息!B$1:D$65536,3,0) -> Jug | AM81: =VLOOKUP(C:C,[1]基础信息!B$1:E$65536,4,0) -> Aluna | AN81: =VLOOKUP(C:C,[1]基础信息!B$1:F$65536,5,0) -> Blue
A82: WH01 | B82: BRITA | C82: 1049188 | D82: 矿泉壶,PS透明壶身配蓝色上盖6支装,,Green Pack 1049188 | E82: * | F82: LT00050093 | G82: 1A02001 | H82: 0000372764 | J82: EA | K82: 70 | L82: 0 | M82: 0 | N82: 70 | P82: 0 | Q82: 0 | R82: 0 | S82: 0 | T82: 0 | U82: 0 | V82: 0 | W82: 0 | X82: 0 | Y82: 0 | AC82: 2024-05-14 | AD82: 2031-05-14 | AE82: 2024-05-14 | AF82: KI4182 | AG82: 1020UR | AI82: N | AJ82: 1 | AK82: =IF(AJ82>$AP$2,$AQ$2,IF(AJ82>$AP$3,$AQ$3,IF(AJ82>$AP$4,$AQ$4,$AQ$5))) -> =<90 | AL82: =VLOOKUP(C:C,[1]基础信息!B$1:D$65536,3,0) -> Jug | AM82: =VLOOKUP(C:C,[1]基础信息!B$1:E$65536,4,0) -> Marella XL | AN82: =VLOOKUP(C:C,[1]基础信息!B$1:F$65536,5,0) -> Blue
A83: WH01 | B83: BRITA | C83: 1046537 | D83: 矿泉壶,PS透明壶身配蓝色上盖1支装,Marella XL 1046537 | E83: 1046537 | F83: LT00050856 | G83: 1A02002 | H83: 0000375678 | J83: EA | K83: 96 | L83: 0 | M83: 0 | N83: 96 | P83: 0 | Q83: 0 | R83: 0 | S83: 0 | T83: 0 | U83: 0 | V83: 0 | W83: 0 | X83: 0 | Y83: 0 | AC83: 2024-06-03 | AD83: 2031-06-03 | AE83: 2024-06-03 | AF83: KI4221 | AG83: 1020UR | AI83: N | AJ83: 1 | AK83: =IF(AJ83>$AP$2,$AQ$2,IF(AJ83>$AP$3,$AQ$3,IF(AJ83>$AP$4,$AQ$4,$AQ$5))) -> =<90 | AL83: =VLOOKUP(C:C,[1]基础信息!B$1:D$65536,3,0) -> Jug | AM83: =VLOOKUP(C:C,[1]基础信息!B$1:E$65536,4,0) -> Marella XL | AN83: =VLOOKUP(C:C,[1]基础信息!B$1:F$65536,5,0) -> Blue
A84: WH01 | B84: BRITA | C84: 1046537 | D84: 矿泉壶,PS透明壶身配蓝色上盖1支装,Marella XL 1046537 | E84: 1046537 | F84: LT00050855 | G84: 1A02003 | H84: 0000375679 | J84: EA | K84: 96 | L84: 0 | M84: 0 | N84: 96 | P84: 0 | Q84: 0 | R84: 0 | S84: 0 | T84: 0 | U84: 0 | V84: 0 | W84: 0 | X84: 0 | Y84: 0 | AC84: 2024-06-03 | AD84: 2031-06-03 | AE84: 2024-06-03 | AF84: KI4227 | AG84: 1020UR | AI84: N | AJ84: 1 | AK84: =IF(AJ84>$AP$2,$AQ$2,IF(AJ84>$AP$3,$AQ$3,IF(AJ84>$AP$4,$AQ$4,$AQ$5))) -> =<90 | AL84: =VLOOKUP(C:C,[1]基础信息!B$1:D$65536,3,0) -> Jug | AM84: =VLOOKUP(C:C,[1]基础信息!B$1:E$65536,4,0) -> Marella XL | AN84: =VLOOKUP(C:C,[1]基础信息!B$1:F$65536,5,0) -> Blue
A85: WH01 | B85: BRITA | C85: 1045641 | D85: "Style XL LED4W Mxplus blue NT CU CNO_x000D_ 滤水壶; Style 中国蓝 一壶一芯" | E85: * | F85: LT00051320 | G85: 1A02004 | H85: 0000377396 | J85: EA | K85: 96 | L85: 0 | M85: 0 | N85: 96 | P85: 0 | Q85: 0 | R85: 0 | S85: 0 | T85: 0 | U85: 0 | V85: 0 | W85: 0 | X85: 0 | Y85: 0 | AC85: 2024-06-15 | AD85: 2031-06-15 | AE85: 2024-06-15 | AF85: YE4236S2 | AG85: 1020UR | AI85: N | AJ85: 1 | AK85: =IF(AJ85>$AP$2,$AQ$2,IF(AJ85>$AP$3,$AQ$3,IF(AJ85>$AP$4,$AQ$4,$AQ$5))) -> =<90 | AL85: =VLOOKUP(C:C,[1]基础信息!B$1:D$65536,3,0) -> Jug | AM85: =VLOOKUP(C:C,[1]基础信息!B$1:E$65536,4,0) -> Mxplus | AN85: =VLOOKUP(C:C,[1]基础信息!B$1:F$65536,5,0) -> Blue
A86: WH01 | B86: BRITA | C86: 1043270 | D86: "Aluna XL ME4W blue BCM CU CNO | E86: * | F86: LT00047611 | G86: 1A02005 | H86: * | I86: * | J86: EA | K86: 96 | L86: 0 | M86: 0 | N86: 96 | P86: 0 | Q86: 0 | R86: 0 | S86: 0 | T86: 0 | U86: 0 | V86: 0 | W86: 0 | X86: 0 | Y86: 0 | AC86: 2024-03-11 | AD86: 2031-03-11 | AE86: 2024-03-11 | AF86: YE4087A3 | AG86: 1020UR | AI86: N | AJ86: 1 | AK86: =IF(AJ86>$AP$2,$AQ$2,IF(AJ86>$AP$3,$AQ$3,IF(AJ86>$AP$4,$AQ$4,$AQ$5))) -> =<90 | AL86: =VLOOKUP(C:C,[1]基础信息!B$1:D$65536,3,0) -> Jug | AM86: =VLOOKUP(C:C,[1]基础信息!B$1:E$65536,4,0) -> Aluna | AN86: =VLOOKUP(C:C,[1]基础信息!B$1:F$65536,5,0) -> Blue
A87: WH01 | B87: BRITA | C87: 1043270 | D87: "Aluna XL ME4W blue BCM CU CNO | E87: * | F87: LT00047611 | G87: 1A02101 | H87: * | I87: * | J87: EA | K87: 96 | L87: 0 | M87: 0 | N87: 96 | P87: 0 | Q87: 0 | R87: 0 | S87: 0 | T87: 0 | U87: 0 | V87: 0 | W87: 0 | X87: 0 | Y87: 0 | AC87: 2024-03-11 | AD87: 2031-03-11 | AE87: 2024-03-11 | AF87: YE4087A3 | AG87: 1020UR | AI87: N | AJ87: 1 | AK87: =IF(AJ87>$AP$2,$AQ$2,IF(AJ87>$AP$3,$AQ$3,IF(AJ87>$AP$4,$AQ$4,$AQ$5))) -> =<90 | AL87: =VLOOKUP(C:C,[1]基础信息!B$1:D$65536,3,0) -> Jug | AM87: =VLOOKUP(C:C,[1]基础信息!B$1:E$65536,4,0) -> Aluna | AN87: =VLOOKUP(C:C,[1]基础信息!B$1:F$65536,5,0) -> Blue
A88: WH01 | B88: BRITA | C88: 1046537 | D88: 矿泉壶,PS透明壶身配蓝色上盖1支装,Marella XL 1046537 | E88: 1046537 | F88: LT00050855 | G88: 1A02102 | H88: 0000375680 | J88: EA | K88: 96 | L88: 0 | M88: 0 | N88: 96 | P88: 0 | Q88: 0 | R88: 0 | S88: 0 | T88: 0 | U88: 0 | V88: 0 | W88: 0 | X88: 0 | Y88: 0 | AC88: 2024-06-03 | AD88: 2031-06-03 | AE88: 2024-06-03 | AF88: KI4227 | AG88: 1020UR | AI88: N | AJ88: 1 | AK88: =IF(AJ88>$AP$2,$AQ$2,IF(AJ88>$AP$3,$AQ$3,IF(AJ88>$AP$4,$AQ$4,$AQ$5))) -> =<90 | AL88: =VLOOKUP(C:C,[1]基础信息!B$1:D$65536,3,0) -> Jug | AM88: =VLOOKUP(C:C,[1]基础信息!B$1:E$65536,4,0) -> Marella XL | AN88: =VLOOKUP(C:C,[1]基础信息!B$1:F$65536,5,0) -> Blue
A89: WH01 | B89: BRITA | C89: 1045641 | D89: "Style XL LED4W Mxplus blue NT CU CNO_x000D_ 滤水壶; Style 中国蓝 一壶一芯" | E89: * | F89: LT00051320 | G89: 1A02103 | H89: 0000377397 | J89: EA | K89: 96 | L89: 0 | M89: 0 | N89: 96 | P89: 0 | Q89: 0 | R89: 0 | S89: 0 | T89: 0 | U89: 0 | V89: 0 | W89: 0 | X89: 0 | Y89: 0 | AC89: 2024-06-15 | AD89: 2031-06-15 | AE89: 2024-06-15 | AF89: YE4236S2 | AG89: 1020UR | AI89: N | AJ89: 1 | AK89: =IF(AJ89>$AP$2,$AQ$2,IF(AJ89>$AP$3,$AQ$3,IF(AJ89>$AP$4,$AQ$4,$AQ$5))) -> =<90 | AL89: =VLOOKUP(C:C,[1]基础信息!B$1:D$65536,3,0) -> Jug | AM89: =VLOOKUP(C:C,[1]基础信息!B$1:E$65536,4,0) -> Mxplus | AN89: =VLOOKUP(C:C,[1]基础信息!B$1:F$65536,5,0) -> Blue
...

Sheet Sheet1
